Workbook
Name JumpTable: '[1]play viewer'!$H$2:$I$10

Sheet Players & Positions
A1: Player Name | B1: Jersey # | C1: Positions Played
A2: Michael Dawson | B2: 73 | C2: X, Y
A3: Joshua Hobbins | B3: 0 | C3: Z, X
A4: Sawyer March | B4: 6 | C4: Z, X
A5: Andrew Martinez | B5: 23 | C5: Q, W, Z, X
A6: Liam Phipps | B6: 16 | C6: C, Z
A7: Agustus Rodriguez | B7: 2 | C7: C
A8: Wesley Simmons | B8: 12 | C8: Q, W, Z, X
A9: Caleb Spivey | B9: 10 | C9: W, Y
A10: Carter Stevens | B10: 8 | C10: W, Y
A11: Parker Woodward | B11: 20 | C11: X, Y
A14: Position Key:
A15: C | B15: =center -> #NAME?
A16: Q | B16: =quarterback -> #NAME?
A17: W | B17: =wide receiver -> #NAME?
A18: X | B18: =wide receiver -> #NAME?
A19: Y | B19: =tight end -> #NAME?
A20: Z | B20: =receiver -> #NAME?

Sheet Play Calls
A1: Play # | B1: Play Name | C1: C (Center) | D1: Q (Quarterback) | E1: W (Wide Receiver) | F1: X (Wide Receiver) | G1: Y (Tight End) | H1: Z (Receiver) | I1: Notes
A2: =IF(B2<>"", ROW()-1, "") -> 1 | B2: Tick | C2: Phipps | D2: Simmons | E2: Woodward | F2: March | G2: Stevens | H2: Spivey
A3: =IF(B3<>"", ROW()-1, "") -> 2 | B3: Tick | C3: Phipps | D3: Simmons | E3: Woodward | F3: March | G3: Stevens | H3: Spivey
A4: =IF(B4<>"", ROW()-1, "") -> 3 | B4: Tick Tock | C4: Phipps | D4: Simmons | E4: Woodward | F4: March | G4: Stevens | H4: Spivey
A5: =IF(B5<>"", ROW()-1, "") -> 4 | B5: Circle Run Option | C5: Phipps | D5: Simmons | E5: Woodward | F5: March | G5: Stevens | H5: Spivey
A6: =IF(B6<>"", ROW()-1, "") -> 5 | B6: Tick | C6: Rodriguez | D6: Simmons | E6: Woodward | F6: Dawson | G6: Martinez | H6: Hobbins
A7: =IF(B7<>"", ROW()-1, "") -> 6 | B7: Airplane Pass Option | C7: Rodriguez | D7: Simmons | E7: Woodward | F7: Dawson | G7: Martinez | H7: Hobbins
A8: =IF(B8<>"", ROW()-1, "") -> 7 | B8: Tick Tock | C8: Rodriguez | D8: Simmons | E8: Woodward | F8: Dawson | G8: Martinez | H8: Hobbins
A9: =IF(B9<>"", ROW()-1, "") -> 8 | B9: Eagle | C9: Rodriguez | D9: Simmons | E9: Woodward | F9: Dawson | G9: Martinez | H9: Hobbins
A10: =IF(B10<>"", ROW()-1, "") -> 9 | B10: Circle Run Option | C10: Phipps | D10: Martinez | E10: March | F10: Simmons | G10: Stevens | H10: Spivey
A11: =IF(B11<>"", ROW()-1, "") -> 10 | B11: Sweep | C11: Phipps | D11: Martinez | E11: March | F11: Simmons | G11: Stevens | H11: Spivey
A12: =IF(B12<>"", ROW()-1, "") -> 11 | B12: Cross | C12: Phipps | D12: Martinez | E12: March | F12: Simmons | G12: Stevens | H12: Spivey
A13: =IF(B13<>"", ROW()-1, "") -> 12 | B13: Tick | C13: Phipps | D13: Martinez | E13: March | F13: Simmons | G13: Stevens | H13: Spivey
... A31: =IF(B31<>"", ROW()-1, "") -> 30 | B31: Sweep | C31: Rodriguez | D31: Martinez | E31: Hobbins | F31: March | G31: Stevens | H31: Simmons
A32: =IF(B32<>"", ROW()-1, "")
A33: =IF(B33<>"", ROW()-1, "")
A34: =IF(B34<>"", ROW()-1, "")
A35: =IF(B35<>"", ROW()-1, "")
A36: =IF(B36<>"", ROW()-1, "")
A37: =IF(B37<>"", ROW()-1, "")
A38: =IF(B38<>"", ROW()-1, "")
A39: =IF(B39<>"", ROW()-1, "")
A40: =IF(B40<>"", ROW()-1, "")
A41: =IF(B41<>"", ROW()-1, "")
A42: =IF(B42<>"", ROW()-1, "")
A43: =IF(B43<>"", ROW()-1, "")
... A51: =IF(B51<>"", ROW()-1, "")

Sheet Stats
A1: Player Name | B1: Jersey # | C1: Available Positions | D1: Total Plays | E1: Times at C | F1: Times at Q | G1: Times at W | H1: Times at X | I1: Times at Y | J1: Times at Z
A2: Michael Dawson | B2: 73 | C2: X,Y | D2: =COUNTIF('Play Calls'!C:C,"*Dawson*")+COUNTIF('Play Calls'!D:D,"*Dawson*")+COUNTIF('Play Calls'!E:E,"*Dawson*")+COUNTIF('Play Calls'!F:F,"*Dawson*")+COUNTIF('Play Calls'!G:G,"*Dawson*")+COUNTIF('Play Calls'!H:H,"*Dawson*") -> 15 | E2: =COUNTIF('Play Calls'!C:C,"*Dawson*") -> 0 | F2: =COUNTIF('Play Calls'!D:D,"*Dawson*") -> 0 | G2: =COUNTIF('Play Calls'!E:E,"*Dawson*") -> 3 | H2: =COUNTIF('Play Calls'!F:F,"*Dawson*") -> 4 | I2: =COUNTIF('Play Calls'!G:G,"*Dawson*") -> 8 | J2: =COUNTIF('Play Calls'!H:H,"*Dawson*") -> 0
A3: Joshua Hobbins | B3: 0 | C3: C,Z | D3: =COUNTIF('Play Calls'!C:C,"*Hobbins*")+COUNTIF('Play Calls'!D:D,"*Hobbins*")+COUNTIF('Play Calls'!E:E,"*Hobbins*")+COUNTIF('Play Calls'!F:F,"*Hobbins*")+COUNTIF('Play Calls'!G:G,"*Hobbins*")+COUNTIF('Play Calls'!H:H,"*Hobbins*") -> 18 | E3: =COUNTIF('Play Calls'!C:C,"*Hobbins*") -> 0 | F3: =COUNTIF('Play Calls'!D:D,"*Hobbins*") -> 0 | G3: =COUNTIF('Play Calls'!E:E,"*Hobbins*") -> 7 | H3: =COUNTIF('Play Calls'!F:F,"*Hobbins*") -> 0 | I3: =COUNTIF('Play Calls'!G:G,"*Hobbins*") -> 0 | J3: =COUNTIF('Play Calls'!H:H,"*Hobbins*") -> 11
A4: Sawyer March | B4: 6 | C4: C,Z | D4: =COUNTIF('Play Calls'!C:C,"*March*")+COUNTIF('Play Calls'!D:D,"*March*")+COUNTIF('Play Calls'!E:E,"*March*")+COUNTIF('Play Calls'!F:F,"*March*")+COUNTIF('Play Calls'!G:G,"*March*")+COUNTIF('Play Calls'!H:H,"*March*") -> 16 | E4: =COUNTIF('Play Calls'!C:C,"*March*") -> 0 | F4: =COUNTIF('Play Calls'!D:D,"*March*") -> 0 | G4: =COUNTIF('Play Calls'!E:E,"*March*") -> 4 | H4: =COUNTIF('Play Calls'!F:F,"*March*") -> 12 | I4: =COUNTIF('Play Calls'!G:G,"*March*") -> 0 | J4: =COUNTIF('Play Calls'!H:H,"*March*") -> 0
A5: Andrew Martinez | B5: 23 | C5: Q,W,Z,X | D5: =COUNTIF('Play Calls'!C:C,"*Martinez*")+COUNTIF('Play Calls'!D:D,"*Martinez*")+COUNTIF('Play Calls'!E:E,"*Martinez*")+COUNTIF('Play Calls'!F:F,"*Martinez*")+COUNTIF('Play Calls'!G:G,"*Martinez*")+COUNTIF('Play Calls'!H:H,"*Martinez*") -> 22 | E5: =COUNTIF('Play Calls'!C:C,"*Martinez*") -> 0 | F5: =COUNTIF('Play Calls'!D:D,"*Martinez*") -> 15 | G5: =COUNTIF('Play Calls'!E:E,"*Martinez*") -> 0 | H5: =COUNTIF('Play Calls'!F:F,"*Martinez*") -> 3 | I5: =COUNTIF('Play Calls'!G:G,"*Martinez*") -> 4 | J5: =COUNTIF('Play Calls'!H:H,"*Martinez*") -> 0
A6: Liam Phipps | B6: 16 | C6: C,Z | D6: =COUNTIF('Play Calls'!C:C,"*Phipps*")+COUNTIF('Play Calls'!D:D,"*Phipps*")+COUNTIF('Play Calls'!E:E,"*Phipps*")+COUNTIF('Play Calls'!F:F,"*Phipps*")+COUNTIF('Play Calls'!G:G,"*Phipps*")+COUNTIF('Play Calls'!H:H,"*Phipps*") -> 16 | E6: =COUNTIF('Play Calls'!C:C,"*Phipps*") -> 16 | F6: =COUNTIF('Play Calls'!D:D,"*Phipps*") -> 0 | G6: =COUNTIF('Play Calls'!E:E,"*Phipps*") -> 0 | H6: =COUNTIF('Play Calls'!F:F,"*Phipps*") -> 0 | I6: =COUNTIF('Play Calls'!G:G,"*Phipps*") -> 0 | J6: =COUNTIF('Play Calls'!H:H,"*Phipps*") -> 0
A7: Agustus Rodriguez | B7: 2 | C7: C | D7: =COUNTIF('Play Calls'!C:C,"*Rodriguez*")+COUNTIF('Play Calls'!D:D,"*Rodriguez*")+COUNTIF('Play Calls'!E:E,"*Rodriguez*")+COUNTIF('Play Calls'!F:F,"*Rodriguez*")+COUNTIF('Play Calls'!G:G,"*Rodriguez*")+COUNTIF('Play Calls'!H:H,"*Rodriguez*") -> 14 | E7: =COUNTIF('Play Calls'!C:C,"*Rodriguez*") -> 14 | F7: =COUNTIF('Play Calls'!D:D,"*Rodriguez*") -> 0 | G7: =COUNTIF('Play Calls'!E:E,"*Rodriguez*") -> 0 | H7: =COUNTIF('Play Calls'!F:F,"*Rodriguez*") -> 0 | I7: =COUNTIF('Play Calls'!G:G,"*Rodriguez*") -> 0 | J7: =COUNTIF('Play Calls'!H:H,"*Rodriguez*") -> 0
A8: Wesley Simmons | B8: 12 | C8: Q,W,Z,X | D8: =COUNTIF('Play Calls'!C:C,"*Simmons*")+COUNTIF('Play Calls'!D:D,"*Simmons*")+COUNTIF('Play Calls'!E:E,"*Simmons*")+COUNTIF('Play Calls'!F:F,"*Simmons*")+COUNTIF('Play Calls'!G:G,"*Simmons*")+COUNTIF('Play Calls'!H:H,"*Simmons*") -> 30 | E8: =COUNTIF('Play Calls'!C:C,"*Simmons*") -> 0 | F8: =COUNTIF('Play Calls'!D:D,"*Simmons*") -> 15 | G8: =COUNTIF('Play Calls'!E:E,"*Simmons*") -> 0 | H8: =COUNTIF('Play Calls'!F:F,"*Simmons*") -> 7 | I8: =COUNTIF('Play Calls'!G:G,"*Simmons*") -> 0 | J8: =COUNTIF('Play Calls'!H:H,"*Simmons*") -> 8
A9: Caleb Spivey | B9: 10 | C9: W,Y | D9: =COUNTIF('Play Calls'!C:C,"*Spivey*")+COUNTIF('Play Calls'!D:D,"*Spivey*")+COUNTIF('Play Calls'!E:E,"*Spivey*")+COUNTIF('Play Calls'!F:F,"*Spivey*")+COUNTIF('Play Calls'!G:G,"*Spivey*")+COUNTIF('Play Calls'!H:H,"*Spivey*") -> 15 | E9: =COUNTIF('Play Calls'!C:C,"*Spivey*") -> 0 | F9: =COUNTIF('Play Calls'!D:D,"*Spivey*") -> 0 | G9: =COUNTIF('Play Calls'!E:E,"*Spivey*") -> 0 | H9: =COUNTIF('Play Calls'!F:F,"*Spivey*") -> 4 | I9: =COUNTIF('Play Calls'!G:G,"*Spivey*") -> 0 | J9: =COUNTIF('Play Calls'!H:H,"*Spivey*") -> 11
A10: Carter Stevens | B10: 8 | C10: W,Y | D10: =COUNTIF('Play Calls'!C:C,"*Stevens*")+COUNTIF('Play Calls'!D:D,"*Stevens*")+COUNTIF('Play Calls'!E:E,"*Stevens*")+COUNTIF('Play Calls'!F:F,"*Stevens*")+COUNTIF('Play Calls'!G:G,"*Stevens*")+COUNTIF('Play Calls'!H:H,"*Stevens*") -> 18 | E10: =COUNTIF('Play Calls'!C:C,"*Stevens*") -> 0 | F10: =COUNTIF('Play Calls'!D:D,"*Stevens*") -> 0 | G10: =COUNTIF('Play Calls'!E:E,"*Stevens*") -> 0 | H10: =COUNTIF('Play Calls'!F:F,"*Stevens*") -> 0 | I10: =COUNTIF('Play Calls'!G:G,"*Stevens*") -> 18 | J10: =COUNTIF('Play Calls'!H:H,"*Stevens*") -> 0
A11: Parker Woodward | B11: 20 | C11: X,Y | D11: =COUNTIF('Play Calls'!C:C,"*Woodward*")+COUNTIF('Play Calls'!D:D,"*Woodward*")+COUNTIF('Play Calls'!E:E,"*Woodward*")+COUNTIF('Play Calls'!F:F,"*Woodward*")+COUNTIF('Play Calls'!G:G,"*Woodward*")+COUNTIF('Play Calls'!H:H,"*Woodward*") -> 16 | E11: =COUNTIF('Play Calls'!C:C,"*Woodward*") -> 0 | F11: =COUNTIF('Play Calls'!D:D,"*Woodward*") -> 0 | G11: =COUNTIF('Play Calls'!E:E,"*Woodward*") -> 16 | H11: =COUNTIF('Play Calls'!F:F,"*Woodward*") -> 0 | I11: =COUNTIF('Play Calls'!G:G,"*Woodward*") -> 0 | J11: =COUNTIF('Play Calls'!H:H,"*Woodward*") -> 0

Sheet Game Summary
A1: Game Summary Dashboard
A3: Total Plays Called: | B3: =COUNTA('Play Calls'!B:B)-1 -> 30
A4: Most Active Player: | B4: =IFERROR(INDEX(Stats!A:A,MATCH(MAX(Stats!D:D),Stats!D:D,0)),"") -> Wesley Simmons
A5: Most Used Play: | B5: =IFERROR(INDEX('Play Calls'!B:B,MODE(MATCH('Play Calls'!B2:B51,'Play Calls'!B2:B51,0))+1),"")
A7: Play Breakdown:
A8: Tick | B8: =COUNTIF('Play Calls'!B:B,"Tick") -> 6
A9: Tick Tock | B9: =COUNTIF('Play Calls'!B:B,"Tick Tock") -> 5
A10: Circle Pass Option | B10: =COUNTIF('Play Calls'!B:B,"Circle Pass Option") -> 2
A11: Circle Run Option | B11: =COUNTIF('Play Calls'!B:B,"Circle Run Option") -> 3
A12: Eagle | B12: =COUNTIF('Play Calls'!B:B,"Eagle") -> 3
A13: Airplane Pass Option | B13: =COUNTIF('Play Calls'!B:B,"Airplane Pass Option") -> 2
A14: Sweep | B14: =COUNTIF('Play Calls'!B:B,"Sweep") -> 4
A15: Cross | B15: =COUNTIF('Play Calls'!B:B,"Cross") -> 5

Sheet Dropdown Lists
A1: C Players | B1: Q Players | C1: W Players | D1: X Players | E1: Y Players | F1: Z Players | G1: Play # | H1: Play Type | I1: Diagram Row
A2: Phipps | B2: Martinez | C2: Martinez | D2: Dawson | E2: Dawson | F2: Hobbins | G2: 1 | H2: Tick | I2: 9
A3: Rodriguez | B3: Simmons | C3: Simmons | D3: Hobbins | E3: Spivey | F3: March | G3: 2 | H3: Tick Tock | I3: 51
C4: Spivey | D4: March | E4: Stevens | F4: Martinez | G4: 3 | H4: Circle - Run Option | I4: 96
C5: Stevens | D5: Martinez | E5: Woodward | F5: Phipps | G5: 4 | H5: Circle - Pass Option | I5: 141
D6: Simmons | F6: Simmons | G6: 5 | H6: Eagle | I6: 186
D7: Woodward | G7: 6 | H7: Airplane - Pass Option | I7: 231
G8: 7 | H8: Sweep | I8: 276
G9: 8 | H9: Cross | I9: 321
G10: 9 | H10: Circle - Reverse | I10: 366
G11: 10
G12: 11
G13: 12
G14: 13
G15: 14
G16: 15
G17: 16
G18: 17
G19: 18
G20: 19
G21: 20
G22: 21
... G31: 30

Sheet Play Diagrams
A1: &#127944; LIONS OFFENSE - MAIN PLAYS
A2: Select players for each position using the dropdowns
A4: Play #1 | E4: Tick
E5: C | F5: Q | G5: W | H5: X | I5: Y | J5: Z
E7: Eligible:
E8: Phipps Rodriguez | F8: Martinez Simmons | G8: Martinez Simmons Spivey Stevens | H8: Dawson Hobbins March Martinez Simmons Woodward | I8: Dawson Spivey Stevens Woodward | J8: Hobbins March Martinez Phipps Simmons
A26: Play #2 | E26: Tick Tock
E27: C | F27: Q | G27: W | H27: X | I27: Y | J27: Z
E29: Eligible:
E30: Phipps Rodriguez | F30: Martinez Simmons | G30: Martinez Simmons Spivey Stevens | H30: Dawson Hobbins March Martinez Simmons Woodward | I30: Dawson Spivey Stevens Woodward | J30: Hobbins March Martinez Phipps Simmons
A48: Play #3 | E48: Circle - Run Option
E49: C | F49: Q | G49: W | H49: X | I49: Y | J49: Z
E51: Eligible:
E52: Phipps Rodriguez | F52: Martinez Simmons | G52: Martinez Simmons Spivey Stevens | H52: Dawson Hobbins March Martinez Simmons Woodward | I52: Dawson Spivey Stevens Woodward | J52: Hobbins March Martinez Phipps Simmons
A70: Play #4 | E70: Circle - Pass Option
E71: C | F71: Q | G71: W | H71: X | I71: Y | J71: Z
E73: Eligible:
E74: Phipps Rodriguez | F74: Martinez Simmons | G74: Martinez Simmons Spivey Stevens | H74: Dawson Hobbins March Martinez Simmons Woodward | I74: Dawson Spivey Stevens Woodward | J74: Hobbins March Martinez Phipps Simmons
A92: Play #5 | E92: Eagle
E93: C | F93: Q | G93: W | H93: X | I93: Y | J93: Z
E95: Eligible:
E96: Phipps Rodriguez | F96: Martinez Simmons | G96: Martinez Simmons Spivey Stevens | H96: Dawson Hobbins March Martinez Simmons Woodward | I96: Dawson Spivey Stevens Woodward | J96: Hobbins March Martinez Phipps Simmons
A114: Play #6 | E114: Airplane - Pass Option
E115: C | F115: Q | G115: W | H115: X | I115: Y | J115: Z
E117: Eligible:
E118: Phipps Rodriguez | F118: Martinez Simmons | G118: Martinez Simmons Spivey Stevens | H118: Dawson Hobbins March Martinez Simmons Woodward | I118: Dawson Spivey Stevens Woodward | J118: Hobbins March Martinez Phipps Simmons
A136: Play #7 | E136: Sweep
E137: C | F137: Q | G137: W | H137: X | I137: Y | J137: Z
E139: Eligible:
E140: Phipps Rodriguez | F140: Martinez Simmons | G140: Martinez Simmons Spivey Stevens | H140: Dawson Hobbins March Martinez Simmons Woodward | I140: Dawson Spivey Stevens Woodward | J140: Hobbins March Martinez Phipps Simmons
A158: Play #8 | E158: Cross
E159: C | F159: Q | G159: W | H159: X | I159: Y | J159: Z
E161: Eligible:
E162: Phipps Rodriguez | F162: Martinez Simmons | G162: Martinez Simmons Spivey Stevens | H162: Dawson Hobbins March Martinez Simmons Woodward | I162: Dawson Spivey Stevens Woodward | J162: Hobbins March Martinez Phipps Simmons
A180: Play #9 | E180: Circle - Reverse
E181: C | F181: Q | G181: W | H181: X | I181: Y | J181: Z
E183: Eligible:
E184: Phipps Rodriguez | F184: Martinez Simmons | G184: Martinez Simmons Spivey Stevens | H184: Dawson Hobbins March Martinez Simmons Woodward | I184: Dawson Spivey Stevens Woodward | J184: Hobbins March Martinez Phipps Simmons

Sheet Play Position Reference
A1: Play # | B1: Play Name | C1: C (Center) | D1: Q (QB) | E1: W (WR) | F1: X (WR) | G1: Y (TE) | H1: Z (Receiver)
A2: 1 | B2: Tick | C2: Phipps, Rodriguez | D2: Martinez, Simmons | E2: Martinez, Simmons, Spivey, Stevens | F2: Dawson, Hobbins, March, Martinez, Simmons, Woodward | G2: Dawson, Spivey, Stevens, Woodward | H2: Hobbins, March, Martinez, Phipps, Simmons
A3: 2 | B3: Tick Tock | C3: Phipps, Rodriguez | D3: Martinez, Simmons | E3: Martinez, Simmons, Spivey, Stevens | F3: Dawson, Hobbins, March, Martinez, Simmons, Woodward | G3: Dawson, Spivey, Stevens, Woodward | H3: Hobbins, March, Martinez, Phipps, Simmons
A4: 3 | B4: Circle - Run Option | C4: Phipps, Rodriguez | D4: Martinez, Simmons | E4: Martinez, Simmons, Spivey, Stevens | F4: Dawson, Hobbins, March, Martinez, Simmons, Woodward | G4: Dawson, Spivey, Stevens, Woodward | H4: Hobbins, March, Martinez, Phipps, Simmons
A5: 4 | B5: Circle - Pass Option | C5: Phipps, Rodriguez | D5: Martinez, Simmons | E5: Martinez, Simmons, Spivey, Stevens | F5: Dawson, Hobbins, March, Martinez, Simmons, Woodward | G5: Dawson, Spivey, Stevens, Woodward | H5: Hobbins, March, Martinez, Phipps, Simmons
A6: 5 | B6: Eagle | C6: Phipps, Rodriguez | D6: Martinez, Simmons | E6: Martinez, Simmons, Spivey, Stevens | F6: Dawson, Hobbins, March, Martinez, Simmons, Woodward | G6: Dawson, Spivey, Stevens, Woodward | H6: Hobbins, March, Martinez, Phipps, Simmons
A7: 6 | B7: Airplane - Pass Option | C7: Phipps, Rodriguez | D7: Martinez, Simmons | E7: Martinez, Simmons, Spivey, Stevens | F7: Dawson, Hobbins, March, Martinez, Simmons, Woodward | G7: Dawson, Spivey, Stevens, Woodward | H7: Hobbins, March, Martinez, Phipps, Simmons
A8: 7 | B8: Sweep | C8: Phipps, Rodriguez | D8: Martinez, Simmons | E8: Martinez, Simmons, Spivey, Stevens | F8: Dawson, Hobbins, March, Martinez, Simmons, Woodward | G8: Dawson, Spivey, Stevens, Woodward | H8: Hobbins, March, Martinez, Phipps, Simmons
A9: 8 | B9: Cross | C9: Phipps, Rodriguez | D9: Martinez, Simmons | E9: Martinez, Simmons, Spivey, Stevens | F9: Dawson, Hobbins, March, Martinez, Simmons, Woodward | G9: Dawson, Spivey, Stevens, Woodward | H9: Hobbins, March, Martinez, Phipps, Simmons
A10: 9 | B10: Circle - Reverse | C10: Phipps, Rodriguez | D10: Martinez, Simmons | E10: Martinez, Simmons, Spivey, Stevens | F10: Dawson, Hobbins, March, Martinez, Simmons, Woodward | G10: Dawson, Spivey, Stevens, Woodward | H10: Hobbins, March, Martinez, Phipps, Simmons
A13: POSITION ELIGIBILITY SUMMARY
A15: Position | B15: Eligible Players
A16: C - Center | B16: Phipps, Rodriguez
A17: Q - Quarterback | B17: Martinez, Simmons
A18: W - Wide Receiver (W) | B18: Martinez, Simmons, Spivey, Stevens
A19: X - Wide Receiver (X) | B19: Dawson, Hobbins, March, Martinez, Simmons, Woodward
A20: Y - Tight End | B20: Dawson, Spivey, Stevens, Woodward
A21: Z - Receiver | B21: Hobbins, March, Martinez, Phipps, Simmons

Sheet Game Plan - 30 Plays
A1: &#127944; LIONS OFFENSE - 30 PLAY GAME PLAN | R1: &#127918; LIVE COACH DASHBOARD
A2: &#9888;&#65039; ADJUSTED: March OUT | Simmons PRIMARY QB (24) | Martinez featured at skill positions (7 targets) | R2: Track results &#8594; See what's HOT &#128293; or COLD &#10052;&#65039; &#8594; Get smart suggestions
A4: # | B4: Diagram | C4: Base Play | D4: Variation | E4: C | F4: Q | G4: W | H4: X | I4: Y | J4: Z | K4: TARGET | L4: Action | M4: Notes | N4: Best For | O4: Result | P4: Yards | R4: &#128202; PLAY TYPE SUCCESS RATES
A5: SEQUENCE 1: Tick Series - Establish Rhythm, Then Counter | R5: Play Type | S5: Called | T5: &#10003; Won | U5: &#10007; Lost | V5: Win % | W5: Status
A6: 1 | B6: &#9654; | C6: Tick | D6: Standard - Z Quick | E6: Phipps | F6: Simmons | G6: Spivey | H6: Martinez | I6: Stevens | J6: Hobbins | K6: X (Martinez) | L6: PASS | M6: Quick pass to Z on slant. Establish rhythm. | N6: &#127937; OPENING DRIVE | O6: &#10003; | P6: 8 | R6: Tick | S6: =COUNTIFS($C$6:$C$41,"*Tick*",$O$6:$O$41,"<>") -> 4 | T6: =COUNTIFS($C$6:$C$41,"*Tick*",$O$6:$O$41,"✓") -> 0 | U6: =COUNTIFS($C$6:$C$41,"*Tick*",$O$6:$O$41,"✗") -> 0 | V6: =IF((T6+U6)=0,"-",T6/(T6+U6)) -> - | W6: =IF(V6="-","⏳ Not Used",IF(V6>=0.6,"🔥 HOT",IF(V6<=0.4,"❄️ COLD","✅ OK"))) -> ⏳ Not Used
A7: 2 | B7: &#9654; | C7: Tick | D7: W Hook Option | E7: Phipps | F7: Simmons | G7: Spivey | H7: Martinez | I7: Stevens | J7: Hobbins | K7: W (Spivey) | L7: PASS | M7: Same look, target W on hook route. | N7: &#127937; OPENING DRIVE | O7: &#10003; | P7: 5 | R7: Tick Tock | S7: =COUNTIFS($C$6:$C$41,"*Tick Tock*",$O$6:$O$41,"<>") -> 1 | T7: =COUNTIFS($C$6:$C$41,"*Tick Tock*",$O$6:$O$41,"✓") -> 0 | U7: =COUNTIFS($C$6:$C$41,"*Tick Tock*",$O$6:$O$41,"✗") -> 0 | V7: =IF((T7+U7)=0,"-",T7/(T7+U7)) -> - | W7: =IF(V7="-","⏳ Not Used",IF(V7>=0.6,"🔥 HOT",IF(V7<=0.4,"❄️ COLD","✅ OK"))) -> ⏳ Not Used
A8: 3 | B8: &#9654; | C8: Tick Tock | D8: X Deep Shot | E8: Phipps | F8: Simmons | G8: Spivey | H8: Dawson | I8: Stevens | J8: Martinez | K8: Z (Martinez) | L8: PASS | M8: Counter off Tick - hit X deep on go route. | N8: &#128205; 2nd &amp; LONG / TAKE SHOT | O8: &#10003; | P8: 15 | R8: Circle Run | S8: =COUNTIFS($C$6:$C$41,"*Circle - Run*",$O$6:$O$41,"<>") -> 1 | T8: =COUNTIFS($C$6:$C$41,"*Circle - Run*",$O$6:$O$41,"✓") -> 0 | U8: =COUNTIFS($C$6:$C$41,"*Circle - Run*",$O$6:$O$41,"✗") -> 0 | V8: =IF((T8+U8)=0,"-",T8/(T8+U8)) -> - | W8: =IF(V8="-","⏳ Not Used",IF(V8>=0.6,"🔥 HOT",IF(V8<=0.4,"❄️ COLD","✅ OK"))) -> ⏳ Not Used
A9: 4 | B9: &#9654; | C9: Tick | D9: Y Corner | E9: Rodriguez | F9: Simmons | G9: Stevens | H9: Martinez | I9: Spivey | J9: Hobbins | K9: Y (Spivey) | L9: PASS | M9: Return to Tick, Y runs corner. | N9: &#127937; 1st DOWN / ANY DOWN | O9: &#10007; | P9: 2 | R9: Circle Pass | S9: =COUNTIFS($C$6:$C$41,"*Circle - Pass*",$O$6:$O$41,"<>") -> 1 | T9: =COUNTIFS($C$6:$C$41,"*Circle - Pass*",$O$6:$O$41,"✓") -> 0 | U9: =COUNTIFS($C$6:$C$41,"*Circle - Pass*",$O$6:$O$41,"✗") -> 0 | V9: =IF((T9+U9)=0,"-",T9/(T9+U9)) -> - | W9: =IF(V9="-","⏳ Not Used",IF(V9>=0.6,"🔥 HOT",IF(V9<=0.4,"❄️ COLD","✅ OK"))) -> ⏳ Not Used
A10: 5 | B10: &#9654; | C10: Circle - Pass Option | D10: Shot Play | E10: Rodriguez | F10: Martinez | G10: Stevens | H10: Woodward | I10: Spivey | J10: Hobbins | K10: X (Woodward) | L10: PASS | M10: Surprise pass to X after selling run fake. | N10: &#128205; 2nd &amp; LONG / TAKE SHOT | O10: &#10003; | P10: 12 | R10: Circle Rev | S10: =COUNTIFS($C$6:$C$41,"*Circle - Reverse*",$O$6:$O$41,"<>") -> 0 | T10: =COUNTIFS($C$6:$C$41,"*Circle - Reverse*",$O$6:$O$41,"✓") -> 0 | U10: =COUNTIFS($C$6:$C$41,"*Circle - Reverse*",$O$6:$O$41,"✗") -> 0 | V10: =IF((T10+U10)=0,"-",T10/(T10+U10)) -> - | W10: =IF(V10="-","⏳ Not Used",IF(V10>=0.6,"🔥 HOT",IF(V10<=0.4,"❄️ COLD","✅ OK"))) -> ⏳ Not Used
A11: SEQUENCE 2: Circle Run Series - Ground Game | R11: Eagle | S11: =COUNTIFS($C$6:$C$41,"*Eagle*",$O$6:$O$41,"<>") -> 0 | T11: =COUNTIFS($C$6:$C$41,"*Eagle*",$O$6:$O$41,"✓") -> 0 | U11: =COUNTIFS($C$6:$C$41,"*Eagle*",$O$6:$O$41,"✗") -> 0 | V11: =IF((T11+U11)=0,"-",T11/(T11+U11)) -> - | W11: =IF(V11="-","⏳ Not Used",IF(V11>=0.6,"🔥 HOT",IF(V11<=0.4,"❄️ COLD","✅ OK"))) -> ⏳ Not Used
A12: 6 | B12: &#9654; | C12: Circle - Run Option | D12: Z Sweep Right | E12: Phipps | F12: Simmons | G12: Stevens | H12: Hobbins | I12: Dawson | J12: Phipps | K12: Z (Phipps) | L12: RUN | M12: Z takes handoff (Phipps releases). X blocks. | N12: &#9889; 3rd &amp; SHORT / GOAL LINE | O12: &#10007; | P12: -2 | R12: Sweep | S12: =COUNTIFS($C$6:$C$41,"*Sweep*",$O$6:$O$41,"<>") -> 0 | T12: =COUNTIFS($C$6:$C$41,"*Sweep*",$O$6:$O$41,"✓") -> 0 | U12: =COUNTIFS($C$6:$C$41,"*Sweep*",$O$6:$O$41,"✗") -> 0 | V12: =IF((T12+U12)=0,"-",T12/(T12+U12)) -> - | W12: =IF(V12="-","⏳ Not Used",IF(V12>=0.6,"🔥 HOT",IF(V12<=0.4,"❄️ COLD","✅ OK"))) -> ⏳ Not Used
A13: 7 | B13: &#9654; | C13: Circle - Run Option | D13: Z Sweep Right | E13: Rodriguez | F13: Simmons | G13: Stevens | H13: Hobbins | I13: Dawson | J13: Hobbins | K13: Z (Hobbins) | L13: RUN | M13: Same concept - Z is primary. | N13: &#9889; 3rd &amp; SHORT / GOAL LINE | R13: Cross | S13: =COUNTIFS($C$6:$C$41,"*Cross*",$O$6:$O$41,"<>") -> 0 | T13: =COUNTIFS($C$6:$C$41,"*Cross*",$O$6:$O$41,"✓") -> 0 | U13: =COUNTIFS($C$6:$C$41,"*Cross*",$O$6:$O$41,"✗") -> 0 | V13: =IF((T13+U13)=0,"-",T13/(T13+U13)) -> - | W13: =IF(V13="-","⏳ Not Used",IF(V13>=0.6,"🔥 HOT",IF(V13<=0.4,"❄️ COLD","✅ OK"))) -> ⏳ Not Used
A14: 8 | B14: &#9654; | C14: Circle - Pass Option | D14: Fake Run, Y Corner | E14: Phipps | F14: Simmons | G14: Stevens | H14: Hobbins | I14: Woodward | J14: Simmons | K14: Y (Woodward) | L14: PASS | M14: Fake to Z, hit Y on corner route. | N14: &#127919; RED ZONE / MISDIRECTION | R14: Airplane | S14: =COUNTIFS($C$6:$C$41,"*Airplane*",$O$6:$O$41,"<>") -> 0 | T14: =COUNTIFS($C$6:$C$41,"*Airplane*",$O$6:$O$41,"✓") -> 0 | U14: =COUNTIFS($C$6:$C$41,"*Airplane*",$O$6:$O$41,"✗") -> 0 | V14: =IF((T14+U14)=0,"-",T14/(T14+U14)) -> - | W14: =IF(V14="-","⏳ Not Used",IF(V14>=0.6,"🔥 HOT",IF(V14<=0.4,"❄️ COLD","✅ OK"))) -> ⏳ Not Used
A15: 9 | B15: &#9654; | C15: Circle - Reverse | D15: W Reverse Left | E15: Rodriguez | F15: Simmons | G15: Stevens | H15: Hobbins | I15: Woodward | J15: Phipps | K15: W (Stevens) | L15: RUN | M15: Big misdirection - W takes reverse. | N15: &#128260; TRICK PLAY / SURPRISE
A16: SEQUENCE 3: Eagle Formation - Stack Attack | R16: &#9889; CURRENT SITUATION (Select Below)
A17: 10 | B17: &#9654; | C17: Eagle | D17: X Out Route | E17: Rodriguez | F17: Martinez | G17: Spivey | H17: Hobbins | I17: Dawson | J17: Phipps | K17: X (Hobbins) | L17: PASS | M17: Stack formation, X runs out. | N17: &#128205; NEED 7+ YARDS | R17: Down: | S17: 2nd | T17: Distance: | U17: Long (7+)
A18: 11 | B18: &#9654; | C18: Eagle | D18: Z Dig | E18: Rodriguez | F18: Simmons | G18: Spivey | H18: Martinez | I18: Dawson | J18: Hobbins | K18: X (Martinez) | L18: PASS | M18: Same look, Z runs dig route. | N18: &#128205; NEED 7+ YARDS | R18: Field Pos: | S18: Midfield
A19: 12 | B19: &#9654; | C19: Sweep | D19: Y Jet Sweep | E19: Phipps | F19: Simmons | G19: Spivey | H19: Martinez | I19: Dawson | J19: Hobbins | K19: Y (Dawson) | L19: RUN | M19: Off Eagle look - Y takes sweep. | N19: &#9889; 3rd &amp; SHORT / GOAL LINE
A20: 13 | B20: &#9654; | C20: Eagle | D20: W Post | E20: Phipps | F20: Simmons | G20: Spivey | H20: Martinez | I20: Stevens | J20: Hobbins | K20: X (Martinez) | L20: PASS | M20: Deep shot to W on post route. | N20: &#128205; NEED 7+ YARDS | R20: &#129504; SMART PLAY SUGGESTIONS
A21: 14 | B21: &#9654; | C21: Cross | D21: A/Z Cross Pattern | E21: Phipps | F21: Simmons | G21: Stevens | H21: Martinez | I21: Dawson | J21: Hobbins | K21: Z (Hobbins) | L21: PASS | M21: Crossing routes - Z is primary. | N21: &#128205; 3rd &amp; MEDIUM / vs ZONE | R21: &#128293; HOT Plays: | T21: =IF(COUNTIF(W6:W14,"*HOT*")=0,"None yet - keep tracking!",IF(ISNUMBER(SEARCH("HOT",W6)),R6&" ","")&IF(ISNUMBER(SEARCH("HOT",W7)),R7&" ","")&IF(ISNUMBER(SEARCH("HOT",W8)),R8&" ","")&IF(ISNUMBER(SEARCH("HOT",W9)),R9&" ","")&IF(ISNUMBER(SEARCH("HOT",W10)),R10&" ","")&IF(ISNUMBER(SEARCH("HOT",W11)),R11&" ","")&IF(ISNUMBER(SEARCH("HOT",W12)),R12&" ","")&IF(ISNUMBER(SEARCH("HOT",W13)),R13&" ","")&IF(ISNUMBER(SEARCH("HOT",W14)),R14&" ","")) -> None yet - keep tracking!
A22: SEQUENCE 4: Airplane Series - Misdirection Passes | R22: &#10052;&#65039; AVOID: | T22: =IF(COUNTIF(W6:W14,"*COLD*")=0,"Nothing cold yet!",IF(ISNUMBER(SEARCH("COLD",W6)),R6&" ","")&IF(ISNUMBER(SEARCH("COLD",W7)),R7&" ","")&IF(ISNUMBER(SEARCH("COLD",W8)),R8&" ","")&IF(ISNUMBER(SEARCH("COLD",W9)),R9&" ","")&IF(ISNUMBER(SEARCH("COLD",W10)),R10&" ","")&IF(ISNUMBER(SEARCH("COLD",W11)),R11&" ","")&IF(ISNUMBER(SEARCH("COLD",W12)),R12&" ","")&IF(ISNUMBER(SEARCH("COLD",W13)),R13&" ","")&IF(ISNUMBER(SEARCH("COLD",W14)),R14&" ","")) -> Nothing cold yet!
A23: 15 | B23: &#9654; | C23: Airplane - Pass Option | D23: X Short | E23: Rodriguez | F23: Martinez | G23: Spivey | H23: Dawson | I23: Stevens | J23: Simmons | K23: X (Dawson) | L23: PASS | M23: Quick pass to X on short route. | N23: &#127919; TAKE A SHOT / 2nd &amp; LONG
A24: 16 | B24: &#9654; | C24: Airplane - Pass Option | D24: Y Sell Fake | E24: Rodriguez | F24: Simmons | G24: Spivey | H24: Dawson | I24: Stevens | J24: Hobbins | K24: Y (Stevens) | L24: PASS | M24: Y sells run fake, releases for pass. | N24: &#127919; TAKE A SHOT / 2nd &amp; LONG | R24: &#128203; SITUATION-BASED PICKS:
A25: 17 | B25: &#9654; | C25: Tick | D25: Change of Pace | E25: Phipps | F25: Simmons | G25: Stevens | H25: Woodward | I25: Spivey | J25: Hobbins | K25: Y (Spivey) | L25: PASS | M25: Slow down tempo, Y on hook. | N25: &#127937; 1st DOWN / ANY DOWN | R25: Short Yardage: | T25: Sweep, Circle Run (look for &#128293;)
A26: 18 | B26: &#9654; | C26: Airplane - Pass Option | D26: W Go Route | E26: Phipps | F26: Simmons | G26: Stevens | H26: Woodward | I26: Spivey | J26: Hobbins | K26: W (Stevens) | L26: PASS | M26: Shot play - W runs deep go. | N26: &#127919; TAKE A SHOT / 2nd &amp; LONG | R26: Need 7+ Yards: | T26: Eagle, Tick Tock, Cross (look for &#128293;)
A27: SEQUENCE 5: Sweep &amp; Reverse - Run Deception | R27: Red Zone: | T27: Circle Pass, Airplane (look for &#128293;)
A28: 19 | B28: &#9654; | C28: Sweep | D28: X Sweep Right | E28: Rodriguez | F28: Simmons | G28: Stevens | H28: Hobbins | I28: Dawson | J28: Martinez | K28: Z (Martinez) | L28: RUN | M28: Establish sweep to X. | N28: &#9889; 3rd &amp; SHORT / GOAL LINE | R28: Backed Up/Safe: | T28: Tick, Sweep (quick/safe options)
A29: 20 | B29: &#9654; | C29: Sweep | D29: Y Sweep Left | E29: Rodriguez | F29: Martinez | G29: Spivey | H29: Woodward | I29: Dawson | J29: Hobbins | K29: Y (Dawson) | L29: RUN | M29: Sweep to Y side - mix it up. | N29: &#9889; 3rd &amp; SHORT / GOAL LINE
A30: 21 | B30: &#9654; | C30: Circle - Reverse | D30: W Reverse Counter | E30: Phipps | F30: Simmons | G30: Stevens | H30: Martinez | I30: Dawson | J30: Hobbins | K30: W (Stevens) | L30: RUN | M30: Counter reverse to W. | N30: &#128260; TRICK PLAY / SURPRISE | R30: &#128200; GAME TOTALS
A31: 22 | B31: &#9654; | C31: Tick Tock | D31: X Deep | E31: Phipps | F31: Simmons | G31: Spivey | H31: Woodward | I31: Dawson | J31: Martinez | K31: Z (Martinez) | L31: PASS | M31: Change up - pass to X deep. | N31: &#128205; 2nd &amp; LONG / TAKE SHOT | R31: Plays Called: | S31: =COUNTIF(O6:O41,"<>") -> 6 | T31: Successful: | U31: =COUNTIF(O6:O41,"✓") -> 0 | V31: Failed: | W31: =COUNTIF(O6:O41,"✗") -> 0
A32: 23 | B32: &#9654; | C32: Tick | D32: Z Slant | E32: Rodriguez | F32: Simmons | G32: Spivey | H32: Martinez | I32: Woodward | J32: Hobbins | K32: Z (Hobbins) | L32: PASS | M32: Quick slant to Z. | N32: &#127937; 1st DOWN / ANY DOWN | R32: Success Rate: | S32: =IF(COUNTIF(O6:O41,"✓")+COUNTIF(O6:O41,"✗")=0,"--",COUNTIF(O6:O41,"✓")/(COUNTIF(O6:O41,"✓")+COUNTIF(O6:O41,"✗"))) -> -- | U32: Total Yards: | V32: =SUMPRODUCT((ISNUMBER(P6:P41))*(P6:P41)) -> 40
A33: SEQUENCE 6: Cross &amp; Deep - Vertical Attack | U33: Touchdowns: | V33: =COUNTIF(P6:P41,"TD") -> 0
A34: 24 | B34: &#9654; | C34: Cross | D34: Z Cross | E34: Phipps | F34: Simmons | G34: Spivey | H34: Hobbins | I34: Dawson | J34: Phipps | K34: Z (Phipps) | L34: PASS | M34: Z runs cross (Phipps releases). | N34: &#128205; 3rd &amp; MEDIUM / vs ZONE | R34: &#127919; RECOMMENDED NEXT PLAY
A35: 25 | B35: &#9654; | C35: Cross | D35: X Post | E35: Phipps | F35: Martinez | G35: Stevens | H35: Woodward | I35: Dawson | J35: Simmons | K35: X (Woodward) | L35: PASS | M35: Same formation, X on post. | N35: &#128205; 3rd &amp; MEDIUM / vs ZONE | R35: =IF(S17="","← Select DOWN & DISTANCE first",IF(U17="Short (1-3)","⚡ Short yardage: Try Sweep or Circle Run",IF(U17="Long (7+)","📍 Need chunk: Try Eagle, Tick Tock, or Cross",IF(U17="Goal Line","🎯 Goal line: Sweep or Circle Run for score","📋 Standard down: Check HOT plays above")))) -> 📍 Need chunk: Try Eagle, Tick Tock, or Cross
A36: 26 | B36: &#9654; | C36: Tick | D36: Safe Play | E36: Rodriguez | F36: Simmons | G36: Spivey | H36: Woodward | I36: Dawson | J36: Hobbins | K36: W (Spivey) | L36: PASS | M36: Safe completion to W. | N36: &#127937; SAFE / BACKED UP
A37: 27 | B37: &#9654; | C37: Cross | D37: Y Deep Corner | E37: Rodriguez | F37: Simmons | G37: Stevens | H37: Woodward | I37: Dawson | J37: Hobbins | K37: Y (Dawson) | L37: PASS | M37: Shot to Y on corner route. | N37: &#127919; NEED BIG PLAY / TRAILING
A38: SEQUENCE 7: Red Zone / End Game
A39: 28 | B39: &#9654; | C39: Circle - Pass Option | D39: Quick Z | E39: Phipps | F39: Simmons | G39: Spivey | H39: Martinez | I39: Stevens | J39: Hobbins | K39: X (Martinez) | L39: PASS | M39: Quick pass to Z in end zone. | N39: &#127937; SAFE / BACKED UP | R39: &#128161; QUICK TIPS
A40: 29 | B40: &#9654; | C40: Tick | D40: C Hook Surprise | E40: Phipps | F40: Simmons | G40: Stevens | H40: Martinez | I40: Woodward | J40: Hobbins | K40: C (Phipps) | L40: PASS | M40: Surprise! Hit C on hook release. | N40: &#127937; 1st DOWN / ANY DOWN | R40: &#8226; After each play: Mark Result (&#10003;/&#10007;) in column O
A41: 30 | B41: &#9654; | C41: Eagle | D41: X Go - TD Shot | E41: Rodriguez | F41: Martinez | G41: Stevens | H41: Dawson | I41: Woodward | J41: Hobbins | K41: X (Dawson) | L41: PASS | M41: Final shot - X runs go for TD. | N41: &#127919; NEED BIG PLAY / TRAILING | R41: &#8226; Watch for &#128293; HOT plays - keep calling them!
...

Sheet PlayViewer
A1: &#128269; PLAY VIEWER - Select Play # to See Roster &amp; Diagram
A2: &#11013;&#65039; Back to Game Plan
A3: PLAY #: | B3: 1 | C3: ◀ SELECT 1-30 from dropdown
A4: PLAY: | B4: =IFERROR(VLOOKUP($B$3*1,'Game Plan - 30 Plays'!$A$6:$L$41,3,FALSE),"") -> Tick | D4: =IFERROR(VLOOKUP($B$3*1,'Game Plan - 30 Plays'!$A$6:$L$41,4,FALSE),"") -> Standard - Z Quick
A5: C | B5: Q | C5: W | D5: X | E5: Y | F5: Z
A6: =IFERROR(VLOOKUP($B$3*1,'Game Plan - 30 Plays'!$A$6:$L$41,5,FALSE),"") -> Phipps | B6: =IFERROR(VLOOKUP($B$3*1,'Game Plan - 30 Plays'!$A$6:$L$41,6,FALSE),"") -> Simmons | C6: =IFERROR(VLOOKUP($B$3*1,'Game Plan - 30 Plays'!$A$6:$L$41,7,FALSE),"") -> Spivey | D6: =IFERROR(VLOOKUP($B$3*1,'Game Plan - 30 Plays'!$A$6:$L$41,8,FALSE),"") -> Martinez | E6: =IFERROR(VLOOKUP($B$3*1,'Game Plan - 30 Plays'!$A$6:$L$41,9,FALSE),"") -> Stevens | F6: =IFERROR(VLOOKUP($B$3*1,'Game Plan - 30 Plays'!$A$6:$L$41,10,FALSE),"") -> Hobbins
A7: &#127919;TARGET: | B7: =IFERROR(VLOOKUP($B$3*1,'Game Plan - 30 Plays'!$A$6:$L$41,11,FALSE),"") -> X (Martinez) | D7: ACTION: | E7: =IFERROR(VLOOKUP($B$3*1,'Game Plan - 30 Plays'!$A$6:$L$41,12,FALSE),"") -> PASS
A8: =IF($B$3="","",IFERROR(HYPERLINK("#PlayViewer!A"&TEXT(VLOOKUP($B$4,'Dropdown Lists'!$H$2:$I$10,2,FALSE),"0"),"▶ JUMP TO DIAGRAM ▼"),"Select a play above")) -> ▶ JUMP TO DIAGRAM ▼
A49: &#11014;&#65039; Back to Top
A51: &#9654; PLAY 2: TICK TOCK
A52: Misdirection timing play
A53: Best for: 2nd down, need chunk yards
A94: &#11014;&#65039; Back to Top
A96: &#9654; PLAY 3: CIRCLE - RUN OPTION
A97: QB keeper/run option
A98: Best for: Short yardage, goal line
A139: &#11014;&#65039; Back to Top
A141: &#9654; PLAY 4: CIRCLE - PASS OPTION
A142: Play action off run fake
A143: Best for: Red zone, misdirection
... A409: &#11014;&#65039; Back to Top
